<?xml version="1.0" ?>
<!-- =================================================================================== -->
<!-- |    This document was autogenerated by xacro from kuka_on_rail.xacro             | -->
<!-- |    EDITING THIS FILE BY HAND IS NOT RECOMMENDED                                 | -->
<!-- =================================================================================== -->
<robot name="kuka_kr120_on_rail" xmlns:xacro="http://www.ros.org/wiki/xacro">
  <!--TODO color definition still in two places, fix-->
  <!--Load color definitions-->
  <!-- Put all the color definitions in a separate file -->
  <material name="Black">
    <color rgba="0.2 0.2 0.2 1.0"/>
  </material>
  <material name="TransparentBlack">
    <color rgba="0.2 0.2 0.2 0.8"/>
  </material>
  <material name="Orange">
    <color rgba="1.0  0.55 0.0 1.0"/>
  </material>
  <material name="Grey">
    <color rgba="0.7 0.7 0.7 1.0"/>
  </material>
  <material name="DarkGrey">
    <color rgba="0.3 0.3 0.3 1.0"/>
  </material>
  <material name="Red">
    <color rgba="0.8 0.0 0.0 1.0"/>
  </material>
  <material name="White">
    <color rgba="1.0 1.0 1.0 1.0"/>
  </material>
  <material name="OffWhite">
    <color rgba="0.8 0.8 0.8 1.0"/>
  </material>
  <material name="Blue">
    <color rgba="0.0 0.0 0.8 1.0"/>
  </material>
  <material name="Green">
    <color rgba="0.0 0.8 0.0 1.0"/>
  </material>
  <material name="TransparentGreen">
    <color rgba="0.0 0.8 0.0 0.5"/>
  </material>
  <!--Create rail to put the kuka arm on-->
  <link name="base_link">
    <visual>
      <geometry>
        <box size="0.2 0.2 0.01"/>
      </geometry>
    </visual>
    <collision>
      <geometry>
        <box size="0.2 0.2 0.01"/>
      </geometry>
    </collision>
  </link>
  <link name="rail">
    <visual>
      <geometry>
        <box size="0.6 3 0.1"/>
      </geometry>
      <origin xyz="0 0 0.05"/>
      <material name="DarkGrey"/>
    </visual>
    <collision>
      <geometry>
        <box size="0.6 3 0.1"/>
      </geometry>
      <origin xyz="0 0 0.05"/>
    </collision>
  </link>
  <joint name="base_to_rail" type="fixed">
    <parent link="base_link"/>
    <child link="rail"/>
    <origin xyz="0 0 1"/>
  </joint>
  <!--Put kuka arm on rail-->
  <!-- LINKS -->
  <!-- base link -->
  <link name="arm_base_link">
    <inertial>
      <origin rpy="0 0 0" xyz="0 0 0"/>
      <mass value="2"/>
      <inertia ixx="0.01" ixy="0" ixz="0" iyy="0.01" iyz="0" izz="0.01"/>
    </inertial>
    <visual>
      <origin rpy="0 0 0" xyz="0 0 0"/>
      <geometry>
        <mesh filename="package://kuka_kr120_support/meshes/kr120r2500pro/visual/base_link.dae"/>
      </geometry>
    </visual>
    <collision>
      <origin rpy="0 0 0" xyz="0 0 0"/>
      <geometry>
        <mesh filename="package://kuka_kr120_support/meshes/kr120r2500pro/collision/base_link.stl"/>
      </geometry>
    </collision>
  </link>
  <!-- link 1 (A1) -->
  <link name="arm_link_1">
    <inertial>
      <origin rpy="0 0 0" xyz="0 0 0"/>
      <mass value="2"/>
      <inertia ixx="0.01" ixy="0" ixz="0" iyy="0.01" iyz="0" izz="0.01"/>
    </inertial>
    <visual>
      <origin rpy="0 0 0" xyz="0 0 0"/>
      <geometry>
        <mesh filename="package://kuka_kr120_support/meshes/kr120r2500pro/visual/link_1.dae"/>
      </geometry>
    </visual>
    <collision>
      <origin rpy="0 0 0" xyz="0 0 0"/>
      <geometry>
        <mesh filename="package://kuka_kr120_support/meshes/kr120r2500pro/collision/link_1.stl"/>
      </geometry>
    </collision>
  </link>
  <!-- link 2 -->
  <link name="arm_link_2">
    <inertial>
      <origin rpy="0 0 0" xyz="0 0 0"/>
      <mass value="2"/>
      <inertia ixx="0.01" ixy="0" ixz="0" iyy="0.01" iyz="0" izz="0.01"/>
    </inertial>
    <visual>
      <origin rpy="0 0 0" xyz="0 0 0"/>
      <geometry>
        <mesh filename="package://kuka_kr120_support/meshes/kr120r2500pro/visual/link_2.dae"/>
      </geometry>
    </visual>
    <collision>
      <origin rpy="0 0 0" xyz="0 0 0"/>
      <geometry>
        <mesh filename="package://kuka_kr120_support/meshes/kr120r2500pro/collision/link_2.stl"/>
      </geometry>
    </collision>
  </link>
  <!-- link 3 -->
  <link name="arm_link_3">
    <inertial>
      <origin rpy="0 0 0" xyz="0 0 0"/>
      <mass value="2"/>
      <inertia ixx="0.01" ixy="0" ixz="0" iyy="0.01" iyz="0" izz="0.01"/>
    </inertial>
    <visual>
      <origin rpy="0 0 0" xyz="0 0 0"/>
      <geometry>
        <mesh filename="package://kuka_kr120_support/meshes/kr120r2500pro/visual/link_3.dae"/>
      </geometry>
    </visual>
    <collision>
      <origin rpy="0 0 0" xyz="0 0 0"/>
      <geometry>
        <mesh filename="package://kuka_kr120_support/meshes/kr120r2500pro/collision/link_3.stl"/>
      </geometry>
    </collision>
  </link>
  <!-- link 4 -->
  <link name="arm_link_4">
    <inertial>
      <origin rpy="0 0 0" xyz="0 0 0"/>
      <mass value="2"/>
      <inertia ixx="0.01" ixy="0" ixz="0" iyy="0.01" iyz="0" izz="0.01"/>
    </inertial>
    <visual>
      <origin rpy="0 0 0" xyz="0 0 0"/>
      <geometry>
        <mesh filename="package://kuka_kr120_support/meshes/kr120r2500pro/visual/link_4.dae"/>
      </geometry>
    </visual>
    <collision>
      <origin rpy="0 0 0" xyz="0 0 0"/>
      <geometry>
        <mesh filename="package://kuka_kr120_support/meshes/kr120r2500pro/collision/link_4.stl"/>
      </geometry>
    </collision>
  </link>
  <!-- link 5 -->
  <link name="arm_link_5">
    <inertial>
      <origin rpy="0 0 0" xyz="0 0 0"/>
      <mass value="2"/>
      <inertia ixx="0.01" ixy="0" ixz="0" iyy="0.01" iyz="0" izz="0.01"/>
    </inertial>
    <visual>
      <origin rpy="0 0 0" xyz="0 0 0"/>
      <geometry>
        <mesh filename="package://kuka_kr120_support/meshes/kr120r2500pro/visual/link_5.dae"/>
      </geometry>
    </visual>
    <collision>
      <origin rpy="0 0 0" xyz="0 0 0"/>
      <geometry>
        <mesh filename="package://kuka_kr120_support/meshes/kr120r2500pro/collision/link_5.stl"/>
      </geometry>
    </collision>
  </link>
  <!-- link 6 -->
  <link name="arm_link_6">
    <inertial>
      <origin rpy="0 0 0" xyz="0 0 0"/>
      <mass value="2"/>
      <inertia ixx="0.01" ixy="0" ixz="0" iyy="0.01" iyz="0" izz="0.01"/>
    </inertial>
    <visual>
      <origin rpy="0 0 0" xyz="0 0 0"/>
      <geometry>
        <mesh filename="package://kuka_kr120_support/meshes/kr120r2500pro/visual/link_6.dae"/>
      </geometry>
    </visual>
    <collision>
      <origin rpy="0 0 0" xyz="0 0 0"/>
      <geometry>
        <mesh filename="package://kuka_kr120_support/meshes/kr120r2500pro/collision/link_6.stl"/>
      </geometry>
    </collision>
  </link>
  <!-- tool 0 -->
  <!-- This frame corresponds to the $FLANGE coordinate system in KUKA KRC controllers. -->
  <link name="arm_tool0"/>
  <!-- END LINKS -->
  <!-- JOINTS -->
  <!-- joint 1 (A1) -->
  <joint name="arm_joint_a1" type="revolute">
    <origin rpy="0 0 0" xyz="0 0 0.675"/>
    <parent link="arm_base_link"/>
    <child link="arm_link_1"/>
    <axis xyz="0 0 -1"/>
    <limit effort="0" lower="-3.22885911619" upper="3.22885911619" velocity="2.72271363311"/>
  </joint>
  <!-- joint 2 (A2) -->
  <joint name="arm_joint_a2" type="revolute">
    <origin rpy="0 0 0" xyz="0.35 0 0"/>
    <parent link="arm_link_1"/>
    <child link="arm_link_2"/>
    <axis xyz="0 1 0"/>
    <limit effort="0" lower="-2.70526034059" upper="0.610865238198" velocity="2.72271363311"/>
  </joint>
  <!-- joint 3 (A3) -->
  <joint name="arm_joint_a3" type="revolute">
    <origin rpy="0 0 0" xyz="1.150 0 0"/>
    <parent link="arm_link_2"/>
    <child link="arm_link_3"/>
    <axis xyz="0 1 0"/>
    <limit effort="0" lower="-2.26892802759" upper="2.68780704807" velocity="2.72271363311"/>
  </joint>
  <!-- joint 4 (A4) -->
  <joint name="arm_joint_a4" type="revolute">
    <origin rpy="0 0 0" xyz="1.0 0 -0.041"/>
    <parent link="arm_link_3"/>
    <child link="arm_link_4"/>
    <axis xyz="-1 0 0"/>
    <limit effort="0" lower="-6.10865238198" upper="6.10865238198" velocity="5.75958653158"/>
  </joint>
  <!-- joint 5 (A5) -->
  <joint name="arm_joint_a5" type="revolute">
    <origin rpy="0 0 0" xyz="0 0 0"/>
    <parent link="arm_link_4"/>
    <child link="arm_link_5"/>
    <axis xyz="0 1 0"/>
    <limit effort="0" lower="-2.26892802759" upper="2.26892802759" velocity="5.75958653158"/>
  </joint>
  <!-- joint 6 (A6) -->
  <joint name="arm_joint_a6" type="revolute">
    <origin rpy="0 0 0" xyz="0 0 0"/>
    <parent link="arm_link_5"/>
    <child link="arm_link_6"/>
    <axis xyz="-1 0 0"/>
    <limit effort="0" lower="-6.10865238198" upper="6.10865238198" velocity="10.7337748998"/>
  </joint>
  <!-- tool frame - fixed frame -->
  <joint name="arm_joint_a6-tool0" type="fixed">
    <parent link="arm_link_6"/>
    <child link="arm_tool0"/>
    <origin rpy="0 1.57079632679 0" xyz="0.215 0 0"/>
  </joint>
  <!-- END JOINTS -->
  <!-- ROS base_link to KUKA $ROBROOT coordinate system transform -->
  <link name="arm_base"/>
  <joint name="arm_base_link-base" type="fixed">
    <origin rpy="0 0 0" xyz="0 0 0"/>
    <parent link="arm_base_link"/>
    <child link="arm_base"/>
  </joint>
  <joint name="rail_to_arm_base_link" type="prismatic">
    <parent link="rail"/>
    <child link="arm_base_link"/>
    <limit effort="1000.0" lower="-1" upper="1" velocity="0.5"/>
    <axis xyz="0 1 0"/>
    <origin rpy="0 0 0" xyz="0 0 0.1"/>
  </joint>
  <!--Add cilinder as dummy welding torch with frame on tip-->
  <link name="welding_torch">
    <visual>
      <geometry>
        <cylinder length="0.2" radius="0.02"/>
      </geometry>
      <origin xyz="0 0 -0.1"/>
      <material name="Black"/>
    </visual>
    <collision>
      <geometry>
        <cylinder length="0.2" radius="0.02"/>
      </geometry>
    </collision>
  </link>
  <joint name="tool_to_torch" type="fixed">
    <parent link="arm_tool0"/>
    <child link="welding_torch"/>
    <origin xyz="0 0 0.2"/>
  </joint>
  <!--Add the turn table to as a part of the robot-->
  <material name="grey">
    <color rgba="0.3 0.3 0.3 1.0"/>
  </material>
  <material name="green">
    <color rgba="0.0 0.8 0.0 0.5"/>
  </material>
  <link name="tab_base_link">
    <visual>
      <geometry>
        <box size="0.2 0.2 0.01"/>
      </geometry>
    </visual>
  </link>
  <link name="tab_support">
    <visual>
      <geometry>
        <box size="1 0.2 2"/>
      </geometry>
      <material name="grey"/>
    </visual>
    <collision>
      <geometry>
        <box size="1 0.2 2"/>
      </geometry>
    </collision>
  </link>
  <link name="tab_table">
    <visual>
      <geometry>
        <box size="1 3 0.1"/>
      </geometry>
      <origin xyz="0 1.6 0"/>
      <material name="green"/>
    </visual>
    <collision>
      <geometry>
        <box size="1 3 0.1"/>
      </geometry>
      <origin xyz="0 1.6 0"/>
    </collision>
  </link>
  <joint name="base_to_support" type="fixed">
    <parent link="tab_base_link"/>
    <child link="tab_support"/>
    <origin rpy="0 0 0" xyz="0 0 1"/>
  </joint>
  <joint name="support_to_table" type="revolute">
    <parent link="tab_support"/>
    <child link="tab_table"/>
    <axis xyz="0 1 0"/>
    <limit effort="1000.0" lower="-3.1415" upper="3.1415" velocity="0.5"/>
    <origin rpy="0 0 0" xyz="0 0 0.5"/>
  </joint>
  <joint name="base_link_to_table_base_link" type="fixed">
    <parent link="base_link"/>
    <child link="tab_base_link"/>
    <origin rpy="0 0 0" xyz="1.5 -1.5 0"/>
  </joint>
</robot>

